<?xml version='1.0'?>
<!-- 【追球v3 新增】e1_25dof.urdf -->
<robot name="E1_111">
    <link name="base_link">
        <inertial>
        <origin xyz="0.046052 4.4711E-05 0.0021883" rpy="0 0 0"/>
        <mass value="3.6563"/>
        <inertia ixx="0.0086992" ixy="-2.2764E-06" ixz="0.00080564" iyy="0.0043435" iyz="-2.3613E-06" izz="0.0086619"/>
        </inertial>
        <visual>
        <origin xyz="0 0 0" rpy="0 0 0"/>
        <geometry>
            <mesh filename="../meshes/base_link.STL"/>
        </geometry>
        <material name="">
            <color rgba="0.89804 0.91765 0.92941 1"/>
        </material>
        </visual>
        <!-- <collision>
        <origin
            xyz="0 0 0"
            rpy="0 0 0" />
        <geometry>
            <mesh
            filename="../meshes/base_link.STL" />
        </geometry>
        </collision> -->
    </link>
    <link name="waist_yaw_link">
        <inertial>
        <origin xyz="-0.0039794 2.0146E-05 0.019034" rpy="0 0 0"/>
        <mass value="0.84518"/>
        <inertia ixx="0.00051116" ixy="-5.0154E-07" ixz="6.3773E-05" iyy="0.00061835" iyz="9.9741E-07" izz="0.00068494"/>
        </inertial>
        <visual>
        <origin xyz="0 0 0" rpy="0 0 0"/>
        <geometry>
            <mesh filename="../meshes/waist_yaw_link.STL"/>
        </geometry>
        <material name="">
            <color rgba="1 1 1 1"/>
        </material>
        </visual>
        <!-- <collision>
        <origin
            xyz="0 0 0"
            rpy="0 0 0" />
        <geometry>
            <mesh
            filename="../meshes/waist_yaw_link.STL" />
        </geometry>
        </collision> -->
    </link>
    <joint name="waist_yaw_joint" type="revolute">
        <origin xyz="0.041941 0 0.064775" rpy="0 0 0"/>
        <parent link="base_link"/>
        <child link="waist_yaw_link"/>
        <axis xyz="0 0 1"/>
        <limit lower="-1.57" upper="1.57" effort="0" velocity="0"/>
    </joint>
    <link name="waist_roll_link">
        <inertial>
        <origin xyz="-0.00055893 -9.001E-05 0.16997" rpy="0 0 0"/>
        <mass value="8.0324"/>
        <inertia ixx="0.060862" ixy="-5.6731E-05" ixz="0.0015231" iyy="0.039402" iyz="-5.476E-05" izz="0.036188"/>
        </inertial>
        <visual>
        <origin xyz="0 0 0" rpy="0 0 0"/>
        <geometry>
            <mesh filename="../meshes/waist_roll_link_wo_head.STL"/>
        </geometry>
        <material name="">
            <color rgba="0.89804 0.91765 0.92941 1"/>
        </material>
        </visual>
        <!-- <collision>
        <origin
            xyz="0 0 0"
            rpy="0 0 0" />
        <geometry>
            <mesh filename="../meshes/waist_roll_link_wo_head.STL"/>
        </geometry>
        </collision> -->
        <collision>
        <origin xyz="0 0 0.22" rpy="0 0 0"/>
        <geometry>
            <box size="0.16 0.2 0.575"/> <!-- 长(x) 宽(y) 高(z) -->
        </geometry>
        </collision>
    </link>
    <!-- 【追球v3 修改】将 `waist_roll_joint` 的 `type` 从 `revolute` 改为 `fixed`，删除对应的 `<axis>` 和 `<limit>` 标签 -->
    <joint name="waist_roll_joint" type="fixed">
        <origin xyz="0 0 0.0282" rpy="0 0 0"/>
        <parent link="waist_yaw_link"/>
        <child link="waist_roll_link"/>
        <axis xyz="1 0 0"/>
        <limit lower="-0.52" upper="0.52" effort="0" velocity="0"/>
    </joint>
    <link name="l_arm_shoulder_pitch_link">
        <inertial>
        <origin xyz="0.0010157 0.051142 -2.0719E-05" rpy="0 0 0"/>
        <mass value="0.65049"/>
        <inertia ixx="0.00037062" ixy="1.3045E-05" ixz="-1.2798E-06" iyy="0.00036895" iyz="-9.4882E-07" izz="0.00035953"/>
        </inertial>
        <visual>
        <origin xyz="0 0 0" rpy="0 0 0"/>
        <geometry>
            <mesh filename="../meshes/l_arm_shoulder_pitch_link.STL"/>
        </geometry>
        <material name="">
            <color rgba="0.69804 0.69804 0.69804 1"/>
        </material>
        </visual>
        <!-- <collision>
        <origin
            xyz="0 0 0"
            rpy="0 0 0" />
        <geometry>
            <mesh
            filename="../meshes/l_arm_shoulder_pitch_link.STL" />
        </geometry>
        </collision> -->
    </link>
    <joint name="l_arm_shoulder_pitch_joint" type="revolute">
        <origin xyz="-0.00096786 0.10919 0.25375" rpy="0.17452 0 0"/>
        <parent link="waist_roll_link"/>
        <child link="l_arm_shoulder_pitch_link"/>
        <axis xyz="0 1 0"/>
        <limit lower="-2.84" upper="2.84" effort="0" velocity="0"/>
    </joint>
    <link name="l_arm_shoulder_roll_link">
        <inertial>
        <origin xyz="-0.0003956 0.028602 -0.069119" rpy="0 0 0"/>
        <mass value="0.76829"/>
        <inertia ixx="0.001047" ixy="1.4853E-06" ixz="-2.8796E-06" iyy="0.00086677" iyz="8.7767E-05" izz="0.00046158"/>
        </inertial>
        <visual>
        <origin xyz="0 0 0" rpy="0 0 0"/>
        <geometry>
            <mesh filename="../meshes/l_arm_shoulder_roll_link.STL"/>
        </geometry>
        <material name="">
            <color rgba="0.69804 0.69804 0.69804 1"/>
        </material>
        </visual>
        <!-- <collision>
        <origin
            xyz="0 0 0"
            rpy="0 0 0" />
        <geometry>
            <mesh
            filename="../meshes/l_arm_shoulder_roll_link.STL" />
        </geometry>
        </collision> -->
        <collision>
        <origin xyz="0.0 0.03 -0.08" rpy="0.1 0 0"/>
        <geometry>
            <cylinder length="0.18" radius="0.0275"/>
        </geometry>
        </collision>
    </link>
    <joint name="l_arm_shoulder_roll_joint" type="revolute">
        <origin xyz="0.00096786 0.058729 0" rpy="-0.17452 0 0"/>
        <parent link="l_arm_shoulder_pitch_link"/>
        <child link="l_arm_shoulder_roll_link"/>
        <axis xyz="1 0 0"/>
        <limit lower="0" upper="2.36" effort="0" velocity="0"/>
    </joint>
    <link name="l_arm_shoulder_yaw_link">
        <inertial>
        <origin xyz="0.010623 0.0011472 -0.027097" rpy="0 0 0"/>
        <mass value="0.76829"/>
        <inertia ixx="0.001047" ixy="1.3465E-06" ixz="-2.935E-06" iyy="0.00088965" iyz="8.7656E-05" izz="0.00043867"/>
        </inertial>
        <visual>
        <origin xyz="0 0 0" rpy="0 0 0"/>
        <geometry>
            <mesh filename="../meshes/l_arm_shoulder_yaw_link.STL"/>
        </geometry>
        <material name="">
            <color rgba="0.69804 0.69804 0.69804 1"/>
        </material>
        </visual>
        <!-- <collision>
        <origin
            xyz="0 0 0"
            rpy="0 0 0" />
        <geometry>
            <mesh
            filename="../meshes/l_arm_shoulder_yaw_link.STL" />
        </geometry>
        </collision> -->
    </link>
    <joint name="l_arm_shoulder_yaw_joint" type="revolute">
        <origin xyz="-0.00099601 0.030407 -0.10688" rpy="0 0 0"/>
        <parent link="l_arm_shoulder_roll_link"/>
        <child link="l_arm_shoulder_yaw_link"/>
        <axis xyz="0 0 1"/>
        <limit lower="-2.62" upper="2.62" effort="0" velocity="0"/>
    </joint>
    <link name="l_arm_elbow_pitch_link">
        <inertial>
        <origin xyz="-0.0093147 6.2366E-05 -0.071674" rpy="0 0 0"/>
        <mass value="0.69323"/>
        <inertia ixx="0.0006568" ixy="-9.8707E-07" ixz="-3.1916E-05" iyy="0.00075304" iyz="-4.2411E-06" izz="0.00034664"/>
        </inertial>
        <visual>
        <origin xyz="0 0 0" rpy="0 0 0"/>
        <geometry>
            <mesh filename="../meshes/l_arm_elbow_pitch_link.STL"/>
        </geometry>
        <material name="">
            <color rgba="0.69804 0.69804 0.69804 1"/>
        </material>
        </visual>
        <!-- <collision>
        <origin
            xyz="0 0 0"
            rpy="0 0 0" />
        <geometry>
            <mesh
            filename="../meshes/l_arm_elbow_pitch_link.STL" />
        </geometry>
        </collision> -->
        <collision>
        <origin xyz="-0.02 0.005 -0.12" rpy="0 0.0 0"/>
        <geometry>
            <cylinder length="0.20" radius="0.0275"/>
        </geometry>
        </collision>
    </link>
    <joint name="l_arm_elbow_pitch_joint" type="revolute">
        <origin xyz="0.020034 0.00026879 -0.10514" rpy="0 0 0"/>
        <parent link="l_arm_shoulder_yaw_link"/>
        <child link="l_arm_elbow_pitch_link"/>
        <axis xyz="0 1 0"/>
        <limit lower="-2.27" upper="0.17" effort="0" velocity="0"/>
    </joint>
    <link name="l_arm_elbow_yaw_link">
        <inertial>
        <origin xyz="-0.00011941 -0.00074665 -0.050578" rpy="0 0 0"/>
        <mass value="0.57183"/>
        <inertia ixx="0.00029045" ixy="2.4459E-08" ixz="4.0896E-08" iyy="0.00031094" iyz="1.5038E-06" izz="0.0001378"/>
        </inertial>
        <visual>
        <origin xyz="0 0 0" rpy="0 0 0"/>
        <geometry>
            <mesh filename="../meshes/l_arm_elbow_yaw_link.STL"/>
        </geometry>
        <material name="">
            <color rgba="0.69804 0.69804 0.69804 1"/>
        </material>
        </visual>
        <!-- <collision>
        <origin
            xyz="0 0 0"
            rpy="0 0 0" />
        <geometry>
            <mesh
            filename="../meshes/l_arm_elbow_yaw_link.STL" />
        </geometry>
        </collision> -->
        <collision>
        <origin
            xyz="-0.02 0.005 -0.20"
            rpy="0 0.0 0" />
        <geometry>
            <cylinder length="0.13" radius="0.04"/>
        </geometry>
        </collision>
    </link>
    <joint name="l_arm_elbow_yaw_joint" type="revolute">
        <origin xyz="-0.0099866 -0.00047817 -0.11036" rpy="0 0 0"/>
        <parent link="l_arm_elbow_pitch_link"/>
        <child link="l_arm_elbow_yaw_link"/>
        <axis xyz="0 0 1"/>
        <limit lower="-2.79" upper="2.79" effort="0" velocity="0"/>
    </joint>
    <link name="r_arm_shoulder_pitch_link">
        <inertial>
        <origin xyz="0.0010157 -0.051142 -2.0719e-05" rpy="0 0 0"/>
        <mass value="0.65049"/>
        <inertia ixx="0.00037062" ixy="-1.3045e-05" ixz="-1.2798E-06" iyy="0.00036895" iyz="9.4882e-07" izz="0.00035953"/>
        </inertial>
        <visual>
        <origin xyz="0 0 0" rpy="0 0 0"/>
        <geometry>
            <mesh filename="../meshes/r_arm_shoulder_pitch_link.STL"/>
        </geometry>
        <material name="">
            <color rgba="0.69804 0.69804 0.69804 1"/>
        </material>
        </visual>
        <!-- <collision>
        <origin
            xyz="0 0 0"
            rpy="0 0 0" />
        <geometry>
            <mesh
            filename="../meshes/r_arm_shoulder_pitch_link.STL" />
        </geometry>
        </collision> -->
    </link>
    <joint name="r_arm_shoulder_pitch_joint" type="revolute">
        <origin xyz="-0.00096786 -0.10919 0.25375" rpy="-0.17452 0 0"/>
        <parent link="waist_roll_link"/>
        <child link="r_arm_shoulder_pitch_link"/>
        <axis xyz="0 1 0"/>
        <limit lower="-2.84" upper="2.84" effort="0" velocity="0"/>
    </joint>
    <link name="r_arm_shoulder_roll_link">
        <inertial>
        <origin xyz="-0.0003956 -0.028602 -0.069119" rpy="0 0 0"/>
        <mass value="0.76829"/>
        <inertia ixx="0.001047" ixy="-1.4853e-06" ixz="-2.8796E-06" iyy="0.00086677" iyz="-8.7767e-05" izz="0.00046158"/>
        </inertial>
        <visual>
        <origin xyz="0 0 0" rpy="0 0 0"/>
        <geometry>
            <mesh filename="../meshes/r_arm_shoulder_roll_link.STL"/>
        </geometry>
        <material name="">
            <color rgba="0.69804 0.69804 0.69804 1"/>
        </material>
        </visual>
        <!-- <collision>
        <origin
            xyz="0 0 0"
            rpy="0 0 0" />
        <geometry>
            <mesh
            filename="../meshes/r_arm_shoulder_roll_link.STL" />
        </geometry>
        </collision> -->
        <collision>
        <origin xyz="0.0 -0.03 -0.08" rpy="-0.1 0 0"/>
        <geometry>
            <cylinder length="0.18" radius="0.0275"/>
        </geometry>
        </collision>
    </link>
    <joint name="r_arm_shoulder_roll_joint" type="revolute">
        <origin xyz="0.00096786 -0.058729 0" rpy="0.17452 0 0"/>
        <parent link="r_arm_shoulder_pitch_link"/>
        <child link="r_arm_shoulder_roll_link"/>
        <axis xyz="1 0 0"/>
        <limit lower="-2.36" upper="0" effort="0" velocity="0"/>
    </joint>
    <link name="r_arm_shoulder_yaw_link">
        <inertial>
        <origin xyz="0.010623 -0.0011472 -0.027097" rpy="0 0 0"/>
        <mass value="0.76829"/>
        <inertia ixx="0.001047" ixy="-1.3465e-06" ixz="-2.935E-06" iyy="0.00088965" iyz="-8.7656e-05" izz="0.00043867"/>
        </inertial>
        <visual>
        <origin xyz="0 0 0" rpy="0 0 0"/>
        <geometry>
            <mesh filename="../meshes/r_arm_shoulder_yaw_link.STL"/>
        </geometry>
        <material name="">
            <color rgba="0.69804 0.69804 0.69804 1"/>
        </material>
        </visual>
        <!-- <collision>
        <origin
            xyz="0 0 0"
            rpy="0 0 0" />
        <geometry>
            <mesh
            filename="../meshes/r_arm_shoulder_yaw_link.STL" />
        </geometry>
        </collision> -->
    </link>
    <joint name="r_arm_shoulder_yaw_joint" type="revolute">
        <origin xyz="-0.00099601 -0.030407 -0.10688" rpy="0 0 0"/>
        <parent link="r_arm_shoulder_roll_link"/>
        <child link="r_arm_shoulder_yaw_link"/>
        <axis xyz="0 0 1"/>
        <limit lower="-2.62" upper="2.62" effort="0" velocity="0"/>
    </joint>
    <link name="r_arm_elbow_pitch_link">
        <inertial>
        <origin xyz="-0.0093147 -6.2366e-05 -0.071674" rpy="0 0 0"/>
        <mass value="0.69323"/>
        <inertia ixx="0.0006568" ixy="9.8707e-07" ixz="-3.1916E-05" iyy="0.00075304" iyz="4.2411e-06" izz="0.00034664"/>
        </inertial>
        <visual>
        <origin xyz="0 0 0" rpy="0 0 0"/>
        <geometry>
            <mesh filename="../meshes/r_arm_elbow_pitch_link.STL"/>
        </geometry>
        <material name="">
            <color rgba="0.69804 0.69804 0.69804 1"/>
        </material>
        </visual>
        <!-- <collision>
        <origin
            xyz="0 0 0"
            rpy="0 0 0" />
        <geometry>
            <mesh
            filename="../meshes/r_arm_elbow_pitch_link.STL" />
        </geometry>
        </collision> -->
        <collision>
        <origin xyz="-0.02 -0.005 -0.12" rpy="0 0.0 0"/>
        <geometry>
            <cylinder length="0.20" radius="0.0275"/>
        </geometry>
        </collision>
    </link>
    <joint name="r_arm_elbow_pitch_joint" type="revolute">
        <origin xyz="0.020034 -0.00026879 -0.10514" rpy="0 0 0"/>
        <parent link="r_arm_shoulder_yaw_link"/>
        <child link="r_arm_elbow_pitch_link"/>
        <axis xyz="0 1 0"/>
        <limit lower="-2.27" upper="0.17" effort="0" velocity="0"/>
    </joint>
    <link name="r_arm_elbow_yaw_link">
        <inertial>
        <origin xyz="-0.00011941 0.00074665 -0.050578" rpy="0 0 0"/>
        <mass value="0.57183"/>
        <inertia ixx="0.00029045" ixy="-2.4459e-08" ixz="4.0896E-08" iyy="0.00031094" iyz="-1.5038e-06" izz="0.0001378"/>
        </inertial>
        <visual>
        <origin xyz="0 0 0" rpy="0 0 0"/>
        <geometry>
            <mesh filename="../meshes/r_arm_elbow_yaw_link.STL"/>
        </geometry>
        <material name="">
            <color rgba="0.69804 0.69804 0.69804 1"/>
        </material>
        </visual>
        <!-- <collision>
        <origin
            xyz="0 0 0"
            rpy="0 0 0" />
        <geometry>
            <mesh
            filename="../meshes/r_arm_elbow_yaw_link.STL" />
        </geometry>
        </collision> -->
        <collision>
        <origin
            xyz="-0.02 -0.005 -0.20"
            rpy="0 0.0 0" />
        <geometry>
            <cylinder length="0.13" radius="0.04"/>
        </geometry>
        </collision>
    </link>
    <joint name="r_arm_elbow_yaw_joint" type="revolute">
        <origin xyz="-0.0099866 0.00047817 -0.11036" rpy="0 0 0"/>
        <parent link="r_arm_elbow_pitch_link"/>
        <child link="r_arm_elbow_yaw_link"/>
        <axis xyz="0 0 1"/>
        <limit lower="-2.79" upper="2.79" effort="0" velocity="0"/>
    </joint>
    <link name="head_yaw_link">
        <visual>
            <origin rpy="0 0 0" xyz="0 0 0"/>
            <geometry>
                <!-- 【追球v3 修改】将 `head_yaw_link` 的 `mesh` 文件名从 `package://摄像头.SLDASM/meshes/head_yaw_link.STL` 改为 `../meshes/head_yaw_link.STL` -->
                <mesh filename="../meshes/head_yaw_link.STL"/>
            </geometry>
            <material name="">
                <color rgba="0.866666666666667 0.909803921568627 1 1"/>
            </material>
        </visual>
        <!-- <collision>
            <origin rpy="0 0 0" xyz="0 0 0"/>
            <geometry>
                <mesh filename="../meshes/head_yaw_link.STL"/>
            </geometry>
        </collision> -->
        <inertial>
            <origin rpy="0 0 0" xyz="-2.741591e-02 4.065893e-04 4.354850e-02"/>
            <mass value="4.549900e-01"/>
            <inertia ixx="2.786634e-04" ixy="9.829866e-07" ixz="4.028327e-05" iyy="2.550811e-04" iyz="-3.313842e-07" izz="2.539163e-04"/>
        </inertial>
    </link>
    <joint name="head_yaw_joint" type="revolute">
        <origin rpy="0 0 0" xyz="-0.00047785 -1.1842E-05 0.37473"/>
        <parent link="waist_roll_link"/>
        <child link="head_yaw_link"/>
        <axis xyz="0 0 1"/>
        <limit effort="0" lower="-1.57" upper="1.57" velocity="0"/>
    </joint>
    <link name="head_pitch_link">
        <visual>
            <origin rpy="0 0 0" xyz="0 0 0"/>
            <geometry>
                <!-- 【追球v3 修改】将 `head_pitch_link` 的 `mesh` 文件名从 `package://摄像头.SLDASM/meshes/head_pitch_link.STL` 改为 `../meshes/head_pitch_link.STL` -->
                <mesh filename="../meshes/head_pitch_link.STL"/>
            </geometry>
            <material name="">
                <color rgba="0.866666666666667 0.909803921568627 1 1"/>
            </material>
        </visual>
        <!-- <collision>
            <origin rpy="0 0 0" xyz="0 0 0"/>
            <geometry>
                <mesh filename="../meshes/head_pitch_link.STL"/>
            </geometry>
        </collision> -->
        <inertial>
            <origin rpy="0 0 0" xyz="5.840945e-02 4.461749e-04 3.235785e-02"/>
            <mass value="6.337500e-01"/>
            <inertia ixx="1.667468e-03" ixy="-6.684467e-06" ixz="-1.172387e-04" iyy="4.004822e-04" iyz="-7.811487e-06" izz="1.742614e-03"/>
        </inertial>
    </link>
    <joint name="head_pitch_joint" type="revolute">
        <origin rpy="0 0 0" xyz="-0.03 0 0.047"/>
        <parent link="head_yaw_link"/>
        <child link="head_pitch_link"/>
        <axis xyz="0 1 0"/>
        <!-- <limit effort="0" lower="-0.78" upper="0.78" velocity="0"/> -->
        <!-- 【追球v3 修改】将 `head_pitch_joint` 的 `limit` 从 `-1.07` 到 `1.07` -->
        <limit effort="0" lower="-0.78" upper="1.07" velocity="0"/> 
    </joint>
    <link name="l_leg_hip_yaw_link">
        <inertial>
        <origin xyz="-0.017915 1.0596E-05 -0.10097" rpy="0 0 0"/>
        <mass value="1.4816"/>
        <inertia ixx="0.0024707" ixy="-5.584E-07" ixz="3.401E-06" iyy="0.0014031" iyz="1.8313E-06" izz="0.0013128"/>
        </inertial>
        <visual>
        <origin xyz="0 0 0" rpy="0 0 0"/>
        <geometry>
            <mesh filename="../meshes/l_leg_hip_yaw_link.STL"/>
        </geometry>
        <material name="">
            <color rgba="0.64706 0.61961 0.58824 1"/>
        </material>
        </visual>
        <!-- <collision>
        <origin
            xyz="0 0 0"
            rpy="0 0 0" />
        <geometry>
            <mesh
            filename="../meshes/l_leg_hip_yaw_link.STL" />
        </geometry>
        </collision> -->
        <collision>
        <origin xyz="-0.020 0.0 -0.12" rpy="0 1.5704 0"/>
        <geometry>
            <cylinder length="0.02" radius="0.05"/>
        </geometry>
        </collision>
    </link>
    <joint name="l_leg_hip_yaw_joint" type="revolute">
        <origin xyz="0.054916 0.09 0.0038519" rpy="0 0.78551 0"/>
        <parent link="base_link"/>
        <child link="l_leg_hip_yaw_link"/>
        <axis xyz="0 0 1"/>
        <limit lower="-0.7" upper="0.92" effort="0" velocity="0"/>
    </joint>
    <link name="l_leg_hip_roll_link">
        <inertial>
        <origin xyz="0.085701 -0.016584 -7.9104E-05" rpy="0 0 0"/>
        <mass value="1.9235"/>
        <inertia ixx="0.0018789" ixy="-1.1425E-05" ixz="7.0321E-06" iyy="0.0038964" iyz="3.0542E-06" izz="0.0023808"/>
        </inertial>
        <visual>
        <origin xyz="0 0 0" rpy="0 0 0"/>
        <geometry>
            <mesh filename="../meshes/l_leg_hip_roll_link.STL"/>
        </geometry>
        <material name="">
            <color rgba="0.64706 0.61961 0.58824 1"/>
        </material>
        </visual>
        <!-- <collision>
        <origin
            xyz="0 0 0"
            rpy="0 0 0" />
        <geometry>
            <mesh
            filename="../meshes/l_leg_hip_roll_link.STL" />
        </geometry>
        </collision> -->
    </link>
    <joint name="l_leg_hip_roll_joint" type="revolute">
        <origin xyz="0 0 -0.1185" rpy="0 0 0"/>
        <parent link="l_leg_hip_yaw_link"/>
        <child link="l_leg_hip_roll_link"/>
        <axis xyz="1 0 0"/>
        <limit lower="-0.7" upper="0.61" effort="0" velocity="0"/>
    </joint>
    <link name="l_leg_hip_pitch_link">
        <inertial>
        <origin xyz="0.014299 0.041463 -0.052859" rpy="0 0 0"/>
        <mass value="4.147"/>
        <inertia ixx="0.017383" ixy="0.00019991" ixz="0.0027472" iyy="0.021696" iyz="-0.00063789" izz="0.0053328"/>
        </inertial>
        <visual>
        <origin xyz="0 0 0" rpy="0 0 0"/>
        <geometry>
            <mesh filename="../meshes/l_leg_hip_pitch_link.STL"/>
        </geometry>
        <material name="">
            <color rgba="0.75294 0.75294 0.75294 1"/>
        </material>
        </visual>
        <!-- <collision>
        <origin
            xyz="0 0 0"
            rpy="0 0 0" />
        <geometry>
            <mesh
            filename="../meshes/l_leg_hip_pitch_link.STL" />
        </geometry>
        </collision> -->
        <collision>
        <origin xyz="0.0 0.02 0.0" rpy="1.5708 0 0"/>
        <geometry>
            <cylinder length="0.07" radius="0.06"/>
        </geometry>
        </collision>
        <collision>
        <origin xyz="0.025 0.015 -0.155" rpy="0 0 0"/>
        <geometry>
            <cylinder length="0.12" radius="0.04"/>
        </geometry>
        </collision>
    </link>
    <joint name="l_leg_hip_pitch_joint" type="revolute">
        <origin xyz="0.101 0 0" rpy="0 -0.78551 0"/>
        <parent link="l_leg_hip_roll_link"/>
        <child link="l_leg_hip_pitch_link"/>
        <axis xyz="0 1 0"/>
        <limit lower="-1.48" upper="0.87" effort="0" velocity="0"/>
    </joint>
    <link name="l_leg_knee_link">
        <inertial>
        <origin xyz="0.013831 0.017997 -0.12305" rpy="0 0 0"/>
        <mass value="3.6766"/>
        <inertia ixx="0.017183" ixy="-3.065E-06" ixz="-0.00054286" iyy="0.018081" iyz="5.2326E-05" izz="0.0016088"/>
        </inertial>
        <visual>
        <origin xyz="0 0 0" rpy="0 0 0"/>
        <geometry>
            <mesh filename="../meshes/l_leg_knee_pitch_link.STL"/>
        </geometry>
        <material name="">
            <color rgba="0.75294 0.75294 0.75294 1"/>
        </material>
        </visual>
        <!-- <collision>
        <origin
            xyz="0 0 0"
            rpy="0 0 0" />
        <geometry>
            <mesh
            filename="../meshes/l_leg_knee_pitch_link.STL" />
        </geometry>
        </collision> -->
        <collision>
        <origin xyz="0.0 0.015 -0.17" rpy="0 0 0"/>
        <geometry>
            <cylinder length="0.26" radius="0.04"/>
        </geometry>
        </collision>
    </link>
    <joint name="l_leg_knee_joint" type="revolute">
        <origin xyz="0.022251 0 -0.25403" rpy="-2.9766E-05 0 0"/>
        <parent link="l_leg_hip_pitch_link"/>
        <child link="l_leg_knee_link"/>
        <axis xyz="0 1 0"/>
        <limit lower="0" upper="2.36" effort="0" velocity="0"/>
    </joint>
    <link name="l_leg_ankle_pitch_link">
        <inertial>
        <origin xyz="-0.0088522 -0.00030887 -6.821E-07" rpy="0 0 0"/>
        <mass value="0.18171"/>
        <inertia ixx="2.3302E-05" ixy="5.7824E-07" ixz="-1.9495E-09" iyy="4.4512E-05" iyz="-5.0057E-12" izz="3.7101E-05"/>
        </inertial>
        <visual>
        <origin xyz="0 0 0" rpy="0 0 0"/>
        <geometry>
            <mesh filename="../meshes/l_leg_ankle_pitch_link.STL"/>
        </geometry>
        <material name="">
            <color rgba="0.75294 0.75294 0.75294 1"/>
        </material>
        </visual>
        <!-- <collision>
        <origin
            xyz="0 0 0"
            rpy="0 0 0" />
        <geometry>
            <mesh
            filename="../meshes/l_leg_ankle_pitch_link.STL" />
        </geometry>
        </collision> -->
    </link>
    <joint name="l_leg_ankle_pitch_joint" type="revolute">
        <origin xyz="3.9185E-05 0.018243 -0.315" rpy="0 0 0"/>
        <parent link="l_leg_knee_link"/>
        <child link="l_leg_ankle_pitch_link"/>
        <axis xyz="0 1 0"/>
        <limit lower="-1.01" upper="0.42" effort="0" velocity="0"/>
    </joint>
    <link name="l_leg_ankle_roll_link">
        <inertial>
            <origin rpy="0 0 0" xyz="6.722747e-02 -1.456690e-06 -2.039773e-02"/>
            <mass value="8.989927e-01"/>
            <inertia ixx="5.377063e-04" ixy="1.348944e-07" ixz="3.275534e-05" iyy="3.510353e-03" iyz="3.464112e-08" izz="3.864054e-03"/>
        </inertial>
        <visual>
        <origin xyz="0 0 0" rpy="0 0 0"/>
        <geometry>
            <mesh filename="../meshes/l_leg_ankle_roll_link.STL"/>
        </geometry>
        <material name="">
            <color rgba="0.64706 0.61961 0.58824 1"/>
        </material>
        </visual>
        <!-- <collision>
        <origin
            xyz="0 0 0"
            rpy="0 0 0" />
        <geometry>
            <mesh
            filename="../meshes/l_leg_ankle_roll_link.STL" />
        </geometry>
        </collision> -->
        <collision>
        <origin xyz="0.036 -0.0005 -0.048" rpy="0 0 0"/>
        <geometry>
            <box size="0.215 0.06 0.026"/>
        </geometry>
        </collision>
    </link>
    <joint name="l_leg_ankle_roll_joint" type="revolute">
        <origin xyz="0 0 0" rpy="0 -0.00010207 0"/>
        <parent link="l_leg_ankle_pitch_link"/>
        <child link="l_leg_ankle_roll_link"/>
        <axis xyz="1 0 0"/>
        <limit lower="-0.26" upper="0.26" effort="0" velocity="0"/>
    </joint>
    <link name="r_leg_hip_yaw_link">
        <inertial>
        <origin xyz="-0.017915 -1.0596e-05 -0.10097" rpy="0 0 0"/>
        <mass value="1.4816"/>
        <inertia ixx="0.00356228" ixy="0.00000589" ixz="-0.00040164" iyy="0.00304199" iyz="0.00000220" izz="0.00190507"/>
        </inertial>
        <visual>
        <origin xyz="0 0 0" rpy="0 0 0"/>
        <geometry>
            <mesh filename="../meshes/r_leg_hip_yaw_link.STL"/>
        </geometry>
        <material name="">
            <color rgba="0.64706 0.61961 0.58824 1"/>
        </material>
        </visual>
        <!-- <collision>
        <origin
            xyz="0 0 0"
            rpy="0 0 0" />
        <geometry>
            <mesh
            filename="../meshes/r_leg_hip_yaw_link.STL" />
        </geometry>
        </collision> -->
        <collision>
        <origin xyz="-0.020 0.0 -0.12" rpy="0 1.5704 0"/>
        <geometry>
            <cylinder length="0.02" radius="0.05"/>
        </geometry>
        </collision>
    </link>
    <joint name="r_leg_hip_yaw_joint" type="revolute">
        <origin xyz="0.054916 -0.09 0.0038519" rpy="0 0.78551 0"/>
        <parent link="base_link"/>
        <child link="r_leg_hip_yaw_link"/>
        <axis xyz="0 0 1"/>
        <limit lower="-0.92" upper="0.7" effort="0" velocity="0"/>
    </joint>
    <link name="r_leg_hip_roll_link">
        <inertial>
        <origin xyz="0.085701 0.016584 -7.9104e-05" rpy="0 0 0"/>
        <mass value="1.9235"/>
        <inertia ixx="0.00224838" ixy="-0.00042919" ixz="0.00001923" iyy="0.00544496" iyz="-0.00000593" izz="0.00424675"/>
        </inertial>
        <visual>
        <origin xyz="0 0 0" rpy="0 0 0"/>
        <geometry>
            <mesh filename="../meshes/r_leg_hip_roll_link.STL"/>
        </geometry>
        <material name="">
            <color rgba="0.64706 0.61961 0.58824 1"/>
        </material>
        </visual>
        <!-- <collision>
        <origin
            xyz="0 0 0"
            rpy="0 0 0" />
        <geometry>
            <mesh
            filename="../meshes/r_leg_hip_roll_link.STL" />
        </geometry>
        </collision> -->
    </link>
    <joint name="r_leg_hip_roll_joint" type="revolute">
        <origin xyz="0 0 -0.1185" rpy="0 0 0"/>
        <parent link="r_leg_hip_yaw_link"/>
        <child link="r_leg_hip_roll_link"/>
        <axis xyz="1 0 0"/>
        <limit lower="-0.61" upper="0.7" effort="0" velocity="0"/>
    </joint>
    <link name="r_leg_hip_pitch_link">
        <inertial>
        <origin xyz="0.014299 -0.041463 -0.052859" rpy="0 0 0"/>
        <mass value="4.147"/>
        <inertia ixx="0.02942136" ixy="-0.00127530" ixz="0.00488391" iyy="0.03104696" iyz="0.00395894" izz="0.00945430"/>
        </inertial>
        <visual>
        <origin xyz="0 0 0" rpy="0 0 0"/>
        <geometry>
            <mesh filename="../meshes/r_leg_hip_pitch_link.STL"/>
        </geometry>
        <material name="">
            <color rgba="0.75294 0.75294 0.75294 1"/>
        </material>
        </visual>
        <!-- <collision>
        <origin
            xyz="0 0 0"
            rpy="0 0 0" />
        <geometry>
            <mesh
            filename="../meshes/r_leg_hip_pitch_link.STL" />
        </geometry>
        </collision> -->
        <collision>
        <origin xyz="0.0 -0.02 0.0" rpy="1.5708 0 0"/>
        <geometry>
            <cylinder length="0.07" radius="0.06"/>
        </geometry>
        </collision>
        <collision>
        <origin xyz="0.025 -0.015 -0.155" rpy="0 0 0"/>
        <geometry>
            <cylinder length="0.12" radius="0.04"/>
        </geometry>
        </collision>
    </link>
    <joint name="r_leg_hip_pitch_joint" type="revolute">
        <origin xyz="0.101 0 0" rpy="0 -0.78551 0"/>
        <parent link="r_leg_hip_roll_link"/>
        <child link="r_leg_hip_pitch_link"/>
        <axis xyz="0 1 0"/>
        <limit lower="-1.48" upper="0.87" effort="0" velocity="0"/>
    </joint>
    <link name="r_leg_knee_link">
        <inertial>
        <origin xyz="0.013831 -0.017997 -0.12305" rpy="0 0 0"/>
        <mass value="3.6766"/>
        <inertia ixx="0.02850776" ixy="-0.00018594" ixz="0.00244949" iyy="0.02892393" iyz="0.00029106" izz="0.00323899"/>
        </inertial>
        <visual>
        <origin xyz="0 0 0" rpy="0 0 0"/>
        <geometry>
            <mesh filename="../meshes/r_leg_knee_pitch_link.STL"/>
        </geometry>
        <material name="">
            <color rgba="0.75294 0.75294 0.75294 1"/>
        </material>
        </visual>
        <!-- <collision>
        <origin
            xyz="0 0 0"
            rpy="0 0 0" />
        <geometry>
            <mesh
            filename="../meshes/r_leg_knee_pitch_link.STL" />
        </geometry>
        </collision> -->
        <collision>
        <origin xyz="0.0 -0.015 -0.17" rpy="0 0 0"/>
        <geometry>
            <cylinder length="0.26" radius="0.04"/>
        </geometry>
        </collision>
    </link>
    <joint name="r_leg_knee_joint" type="revolute">
        <origin xyz="0.022251 0 -0.25403" rpy="2.9766e-05 0 0"/>
        <parent link="r_leg_hip_pitch_link"/>
        <child link="r_leg_knee_link"/>
        <axis xyz="0 1 0"/>
        <limit lower="0" upper="2.36" effort="0" velocity="0"/>
    </joint>
    <link name="r_leg_ankle_pitch_link">
        <inertial>
        <origin xyz="-0.0088522 0.00030887 -6.821e-07" rpy="0 0 0"/>
        <mass value="0.18171"/>
        <inertia ixx="0.00001879" ixy="-0.00000017" ixz="0.00000000" iyy="0.00004121" iyz="0.00000000" izz="0.00003542"/>
        </inertial>
        <visual>
        <origin xyz="0 0 0" rpy="0 0 0"/>
        <geometry>
            <mesh filename="../meshes/r_leg_ankle_pitch_link.STL"/>
        </geometry>
        <material name="">
            <color rgba="0.75294 0.75294 0.75294 1"/>
        </material>
        </visual>
        <!-- <collision>
        <origin
            xyz="0 0 0"
            rpy="0 0 0" />
        <geometry>
            <mesh
            filename="../meshes/r_leg_ankle_pitch_link.STL" />
        </geometry>
        </collision> -->
    </link>
    <joint name="r_leg_ankle_pitch_joint" type="revolute">
        <origin xyz="3.9185e-05 -0.018243 -0.315" rpy="0 0 0"/>
        <parent link="r_leg_knee_link"/>
        <child link="r_leg_ankle_pitch_link"/>
        <axis xyz="0 1 0"/>
        <limit lower="-1.01" upper="0.42" effort="0" velocity="0"/>
    </joint>
    <link name="r_leg_ankle_roll_link">
        <inertial>
        <origin xyz="0.021092 7.0109e-05 -0.03295" rpy="0 0 0"/>
        <mass value="0.56573"/>
        <inertia ixx="0.0001959" ixy="-1.9932e-06" ixz="6.0274E-06" iyy="0.001019" iyz="-1.2455e-08" izz="0.0010733"/>
        </inertial>
        <visual>
        <origin xyz="0 0 0" rpy="0 0 0"/>
        <geometry>
            <mesh filename="../meshes/r_leg_ankle_roll_link.STL"/>
        </geometry>
        <material name="">
            <color rgba="0.64706 0.61961 0.58824 1"/>
        </material>
        </visual>
        <!-- <collision>
        <origin
            xyz="0 0 0"
            rpy="0 0 0" />
        <geometry>
            <mesh
            filename="../meshes/r_leg_ankle_roll_link.STL" />
        </geometry>
        </collision> -->
        <collision>
        <origin xyz="0.036 0.0005 -0.048" rpy="0 0 0"/>
        <geometry>
            <box size="0.215 0.06 0.026"/>
        </geometry>
        </collision>
    </link>
    <joint name="r_leg_ankle_roll_joint" type="revolute">
        <origin xyz="0 0 0" rpy="0 -0.00010207 0"/>
        <parent link="r_leg_ankle_pitch_link"/>
        <child link="r_leg_ankle_roll_link"/>
        <axis xyz="1 0 0"/>
        <limit lower="-0.26" upper="0.26" effort="0" velocity="0"/>
    </joint>
</robot>